Workbook

Sheet Demographic
A1: Participant ID | B1: Initials | C1: Sex | D1: Age | E1: Scan | F1: Quality | G1: Scan | H1: Quality | I1: Scan | J1: Quality | K1: Scan | L1: Quality | M1: Scan | N1: Quality | O1: Scan | P1: Quality | Q1: Scan | R1: Quality | S1: Scan | T1: Quality
A2: Initials | B2: Sex | C2: Age
A5: DP-02DG | B5: M | C5: 43
A6: DP-03JR | B6: M | C6: 47
A7: DP-04RH | B7: M | C7: 70
A8: DP-05TA | B8: M | C8: 60
A9: DP-06JF | B9: F | C9: 68
A10: DP-07AC | B10: M | C10: 57
A11: DP-10JP | B11: M | C11: 64 | E11: Blå er age-matched group
A12: DP-11DC | B12: F | C12: 47
A13: DP-12SR | B13: F | C13: 71
A14: DP-13DH | B14: M | C14: 66
A15: DP-14AT | B15: M | C15: 58
A16: DP15NL | B16: M | C16: 62
A24: Initials | B24: Sex | C24: Age
A25: hp-53RM | B25: M | C25: 26
A26: HP-03MB | B26: F | C26: 28
A27: HP-04GU | B27: F | C27: 31
A28: HP-05IT | B28: M | C28: 24
A29: HP-06MF | B29: F | C29: 26
A30: HP-07VM | B30: F | C30: 29
A31: HP-08AF | B31: M | C31: 33
A32: HP-09PM | B32: F | C32: 27
A33: HP-10ES | B33: F | C33: 26
A34: HP-11AG | B34: F | C34: 22
A35: AR | B35: F | C35: 42
A36: JA | B36: F | C36: 58
... A79: HP-60PW | B79: F | C79: 71

Sheet Vessel area density
D1: SESSION 1 | P1: Coefficient of repeatibility analysis from the baseline scans | T1: SESSION 2 | AF1: Coefficient of repeatibility analysis from the baseline scans | AI1: SESSION 3 | AU1: Coefficient of repeatibility analysis from the baseline scans | AX1: SESSION 4 | BJ1: Coefficient of repeatibility analysis from the baseline scans
D2: Baseline | I2: Ischemia | J2: PORH | Q2: Median value of 5 measures | R2: PORH MAX | S2: Absolute diff between PORH and Median | T2: Baseline | Y2: Ischemia | Z2: PORH | AI2: Baseline | AN2: Ischemia | AO2: PORH | AX2: Baseline | BC2: Ischemia | BD2: PORH
A3: Age group | B3: Health/disease | C3: Participant ID | D3: Scan 1 | E3: Scan 2 | F3: Scan 3 | G3: Scan 4 | H3: Scan 5 | I3: Scan 6 | J3: Scan 7 | K3: Scan 8 | L3: Scan 9 | M3: Scan 10 | N3: Scan 11 | O3: Scan 12 | P3: Variance of (SD) | T3: Scan 1 | U3: Scan 2 | V3: Scan 3 | W3: Scan 4 | X3: Scan 5 | Y3: Scan 6 | Z3: Scan 7 | AA3: Scan 8 | AB3: Scan 9 | AC3: Scan 10 | AD3: Scan 11 | AE3: Scan 12 | AF3: Variance of (SD) | AI3: Scan 1 | AJ3: Scan 2 | AK3: Scan 3 | AL3: Scan 4 | AM3: Scan 5 | AN3: Scan 6 | AO3: Scan 7 | AP3: Scan 8 | AQ3: Scan 9 | AR3: Scan 10 | AS3: Scan 11 | AT3: Scan 12 | AU3: Variance of (SD) | AX3: Scan 1 | AY3: Scan 2 | AZ3: Scan 3 | BA3: Scan 4 | BB3: Scan 5 | BC3: Scan 6 | BD3: Scan 7 | BE3: Scan 8 | BF3: Scan 9 | BG3: Scan 10 | BH3: Scan 11 | BI3: Scan 12 | BJ3: Variance of (SD)
B4: Healthy | C4: HP-03 | D4: 18 | E4: 22 | F4: 27 | G4: 29 | H4: 21 | I4: 14 | J4: 13 | K4: 13 | L4: 17 | M4: 17 | P4: =IFERROR(STDEVA(D4:H4),#N/A) -> 4.5055521 | Q4: =MEDIAN(D4:H4) -> 22 | R4: =MAX(J4:O4) -> 17 | S4: =100*(R4-Q4)/Q4 -> -22.727273 | T4: 23 | U4: 28 | V4: 24 | W4: 26 | X4: 25 | Y4: 13 | Z4: 41 | AA4: 33 | AB4: 37 | AC4: 34 | AF4: =IFERROR(STDEVA(T4:X4),#N/A) -> 1.9235384 | AU4: =IFERROR(STDEVA(AI4:AM4),#N/A) -> #N/A | BJ4: =IFERROR(STDEVA(AX4:BB4),#N/A) -> #N/A
B5: Healthy | C5: HP-05 | D5: 40 | E5: 41 | F5: 48 | G5: 51 | H5: 50 | I5: 20 | J5: 60 | K5: 59 | L5: 60 | M5: 57 | P5: =IFERROR(STDEVA(D5:H5),#N/A) -> 5.1478151 | Q5: =MEDIAN(D5:H5) -> 48 | R5: =MAX(J5:O5) -> 60 | S5: =100*(R5-Q5)/Q5 -> 25 | AF5: =IFERROR(STDEVA(T5:X5),#N/A) -> #N/A | AU5: =IFERROR(STDEVA(AI5:AM5),#N/A) -> #N/A | BJ5: =IFERROR(STDEVA(AX5:BB5),#N/A) -> #N/A
B6: Healthy | C6: HP-06 | D6: 46 | E6: 47 | F6: 44 | G6: 47 | H6: 50 | I6: 25 | J6: 64 | K6: 67 | L6: 63 | M6: 59 | P6: =IFERROR(STDEVA(D6:H6),#N/A) -> 2.1679483 | Q6: =MEDIAN(D6:H6) -> 47 | R6: =MAX(J6:O6) -> 67 | S6: =100*(R6-Q6)/Q6 -> 42.553191 | AF6: =IFERROR(STDEVA(T6:X6),#N/A) -> #N/A | AU6: =IFERROR(STDEVA(AI6:AM6),#N/A) -> #N/A | BJ6: =IFERROR(STDEVA(AX6:BB6),#N/A) -> #N/A
B7: Healthy | C7: HP-07 | D7: 34 | E7: 27 | F7: 21 | G7: 20 | H7: 28 | I7: 21 | J7: 12 | K7: 15 | L7: 22 | M7: 21 | P7: =IFERROR(STDEVA(D7:H7),#N/A) -> 5.7008771 | Q7: =MEDIAN(D7:H7) -> 27 | R7: =MAX(J7:O7) -> 22 | S7: =100*(R7-Q7)/Q7 -> -18.518519 | T7: 34 | U7: 37 | V7: 38 | W7: 38 | X7: 40 | Y7: 17 | Z7: 57 | AA7: 57 | AB7: 48 | AC7: 51 | AF7: =IFERROR(STDEVA(T7:X7),#N/A) -> 2.1908902 | AU7: =IFERROR(STDEVA(AI7:AM7),#N/A) -> #N/A | BJ7: =IFERROR(STDEVA(AX7:BB7),#N/A) -> #N/A
B8: Healthy | C8: HP-09 | D8: 26 | E8: 33 | F8: 38 | G8: 38 | H8: 33 | I8: 19 | J8: 68 | K8: 62 | L8: 57 | M8: 53 | P8: =IFERROR(STDEVA(D8:H8),#N/A) -> 4.929503 | Q8: =MEDIAN(D8:H8) -> 33 | R8: =MAX(J8:O8) -> 68 | S8: =100*(R8-Q8)/Q8 -> 106.06061 | AF8: =IFERROR(STDEVA(T8:X8),#N/A) -> #N/A | AU8: =IFERROR(STDEVA(AI8:AM8),#N/A) -> #N/A | BJ8: =IFERROR(STDEVA(AX8:BB8),#N/A) -> #N/A
B9: Healthy | C9: HP-10 | D9: 31 | E9: 32 | F9: 31 | G9: 32 | H9: 28 | I9: 30 | J9: 54 | K9: 39 | L9: 33 | M9: 35 | P9: =IFERROR(STDEVA(D9:H9),#N/A) -> 1.6431677 | Q9: =MEDIAN(D9:H9) -> 31 | R9: =MAX(J9:O9) -> 54 | S9: =100*(R9-Q9)/Q9 -> 74.193548 | AF9: =IFERROR(STDEVA(T9:X9),#N/A) -> #N/A | AU9: =IFERROR(STDEVA(AI9:AM9),#N/A) -> #N/A | BJ9: =IFERROR(STDEVA(AX9:BB9),#N/A) -> #N/A
B10: Healthy | C10: HP-11 | D10: 26 | E10: 35 | F10: 25 | G10: 28 | H10: 27 | I10: 27 | J10: 51 | K10: 57 | L10: 50 | M10: 38 | P10: =IFERROR(STDEVA(D10:H10),#N/A) -> 3.9623226 | Q10: =MEDIAN(D10:H10) -> 27 | R10: =MAX(J10:O10) -> 57 | S10: =100*(R10-Q10)/Q10 -> 111.11111 | AF10: =IFERROR(STDEVA(T10:X10),#N/A) -> #N/A | AU10: =IFERROR(STDEVA(AI10:AM10),#N/A) -> #N/A | BJ10: =IFERROR(STDEVA(AX10:BB10),#N/A) -> #N/A
B11: Healthy | C11: HP-18 | D11: 26 | E11: 29 | F11: 55 | G11: 56 | H11: 50 | I11: 18 | J11: 66 | K11: 68 | L11: 67 | M11: 67 | P11: =IFERROR(STDEVA(D11:H11),#N/A) -> 14.549914 | Q11: =MEDIAN(D11:H11) -> 50 | R11: =MAX(J11:O11) -> 68 | S11: =100*(R11-Q11)/Q11 -> 36 | AF11: =IFERROR(STDEVA(T11:X11),#N/A) -> #N/A | AU11: =IFERROR(STDEVA(AI11:AM11),#N/A) -> #N/A | BJ11: =IFERROR(STDEVA(AX11:BB11),#N/A) -> #N/A
B12: Healthy | C12: HP-24 | D12: 30 | E12: 35 | F12: 37 | G12: 36 | H12: 32 | I12: 23 | J12: 41 | K12: 42 | L12: 37 | M12: 43 | N12: 35 | O12: 31 | P12: =IFERROR(STDEVA(D12:H12),#N/A) -> 2.9154759 | Q12: =MEDIAN(D12:H12) -> 35 | R12: =MAX(J12:O12) -> 43 | S12: =100*(R12-Q12)/Q12 -> 22.857143 | AF12: =IFERROR(STDEVA(T12:X12),#N/A) -> #N/A | AU12: =IFERROR(STDEVA(AI12:AM12),#N/A) -> #N/A | BJ12: =IFERROR(STDEVA(AX12:BB12),#N/A) -> #N/A
P13: Mean of median | Q13: =AVERAGE(Q4:Q12) -> 35.555556 | R13: =AVERAGE(R4:R12) -> 50.666667 | S13: =AVERAGE(S4:S12) -> 41.836645 | AF13: =IFERROR(STDEVA(T13:X13),#N/A) -> #N/A | AU13: =IFERROR(STDEVA(AI13:AM13),#N/A) -> #N/A | BJ13: =IFERROR(STDEVA(AX13:BB13),#N/A) -> #N/A
P14: SD | Q14: =STDEVA(Q4:Q12) -> 10.321229 | R14: =STDEVA(R4:R12) -> 19.429359 | S14: =STDEVA(S4:S12) -> 48.036649 | AF14: =IFERROR(STDEVA(T14:X14),#N/A) -> #N/A | AU14: =IFERROR(STDEVA(AI14:AM14),#N/A) -> #N/A | BJ14: =IFERROR(STDEVA(AX14:BB14),#N/A) -> #N/A
P15: COV | Q15: =Q14/Q13 -> 0.29028458 | R15: =R14/R13 -> 0.3834742 | S15: =S14/S13 -> 1.1481955 | AF15: =IFERROR(STDEVA(T15:X15),#N/A) -> #N/A | AU15: =IFERROR(STDEVA(AI15:AM15),#N/A) -> #N/A | BJ15: =IFERROR(STDEVA(AX15:BB15),#N/A) -> #N/A
O16: Number of scans per subject | P16: 5 | Q16: <-insert correct numbers before the analysis | AE16: Number of scans per subject | AF16: 5 | AG16: <-insert correct numbers before the analysis | AT16: Number of scans per subject | AU16: 5 | AV16: <-insert correct numbers before the analysis | BI16: Number of scans per subject | BJ16: 5 | BK16: <-insert correct numbers before the analysis
O17: Number of subjects | P17: 9 | Q17: <-insert correct numbers before the analysis | AE17: Number of subjects | AF17: 10 | AG17: <-insert correct numbers before the analysis | AT17: Number of subjects | AU17: 10 | AV17: <-insert correct numbers before the analysis | BI17: Number of subjects | BJ17: 10 | BK17: <-insert correct numbers before the analysis
O18: Within SD | P18: =SQRT(AVERAGE(P4:P12)) -> 2.249014 | AE18: Within SD | AF18: =SQRT(AVERAGE(AF4:AF15)) -> #N/A | AT18: Within SD | AU18: =SQRT(AVERAGE(AU4:AU15)) -> #N/A | BI18: Within SD | BJ18: =SQRT(AVERAGE(BJ4:BJ15)) -> #N/A
O19: CR | P19: =2.77*P18 -> 6.2297688 | AE19: CR | AF19: =2.77*AF18 -> #N/A | AT19: CR | AU19: =2.77*AU18 -> #N/A | BI19: CR | BJ19: =2.77*BJ18 -> #N/A
O20: CI_A | P20: =P19-(1.96*(P18/(SQRT(2*P17*(P16-1))))) -> 5.7102731 | AE20: CI_A | AF20: =AF19-(1.96*(AF18/(SQRT(2*AF17*(AF16-1))))) -> #N/A | AT20: CI_A | AU20: =AU19-(1.96*(AU18/(SQRT(2*AU17*(AU16-1))))) -> #N/A | BI20: CI_A | BJ20: =BJ19-(1.96*(BJ18/(SQRT(2*BJ17*(BJ16-1))))) -> #N/A
O21: CI_B | P21: =P19+(1.96*(P18/(SQRT(2*P17*(P16-1))))) -> 6.7492645 | AE21: CI_B | AF21: =AF19+(1.96*(AF18/(SQRT(2*AF17*(AF16-1))))) -> #N/A | AT21: CI_B | AU21: =AU19+(1.96*(AU18/(SQRT(2*AU17*(AU16-1))))) -> #N/A | BI21: CI_B | BJ21: =BJ19+(1.96*(BJ18/(SQRT(2*BJ17*(BJ16-1))))) -> #N/A
A23: 30-39 | B23: Healthy | C23: HP-04 | D23: 34 | E23: 31 | F23: 36 | G23: 40 | H23: 46 | I23: 14 | J23: 56 | K23: 47 | L23: 43 | M23: 43 | P23: =IFERROR(STDEVA(D23:H23),#N/A) -> 5.8137767 | Q23: =MEDIAN(D23:H23) -> 36 | R23: =MAX(J23:O23) -> 56 | S23: =100*(R23-Q23)/Q23 -> 55.555556
B24: Healthy | C24: HP-08 | D24: 28 | E24: 41 | F24: 41 | G24: 39 | H24: 36 | I24: 20 | J24: 65 | K24: 62 | L24: 60 | M24: 57 | P24: =IFERROR(STDEVA(D24:H24),#N/A) -> 5.4313902 | Q24: =MEDIAN(D24:H24) -> 39 | R24: =MAX(J24:O24) -> 65 | S24: =100*(R24-Q24)/Q24 -> 66.666667
B25: Healthy | C25: HP-19 | D25: 15 | E25: 24 | F25: 16 | G25: 23 | H25: 30 | I25: 15 | J25: 46 | K25: 47 | L25: 58 | M25: 35 | P25: =IFERROR(STDEVA(D25:H25),#N/A) -> 6.1886994 | Q25: =MEDIAN(D25:H25) -> 23 | R25: =MAX(J25:O25) -> 58 | S25: =100*(R25-Q25)/Q25 -> 152.17391
B26: Healthy | C26: HP-21 | D26: 36 | E26: 41 | F26: 46 | G26: 41 | H26: 44 | I26: 16 | J26: 51 | K26: 44 | L26: 41 | M26: 41 | N26: 42 | O26: 42 | P26: =IFERROR(STDEVA(D26:H26),#N/A) -> 3.7815341 | Q26: =MEDIAN(D26:H26) -> 41 | R26: =MAX(J26:O26) -> 51 | S26: =100*(R26-Q26)/Q26 -> 24.390244 | T26: 38 | U26: 43 | V26: 41 | W26: 37 | X26: 38 | Y26: 24 | Z26: 43 | AA26: 49 | AB26: 51 | AC26: 44 | AD26: 47 | AE26: 45
B27: Healthy | C27: HP-22 | D27: 46 | E27: 24 | F27: 52 | G27: 52 | H27: 54 | I27: 22 | J27: 41 | K27: 35 | L27: 36 | M27: 34 | N27: 44 | O27: 40 | P27: =IFERROR(STDEVA(D27:H27),#N/A) -> 12.441865 | Q27: =MEDIAN(D27:H27) -> 52 | R27: =MAX(J27:O27) -> 44 | S27: =100*(R27-Q27)/Q27 -> -15.384615
B28: Healthy | C28: HP-30 | D28: 17 | E28: 24 | F28: 28 | G28: 29 | H28: 23 | I28: 24 | J28: 22 | K28: 33 | L28: 36 | M28: 35 | N28: 35 | O28: 32 | P28: =IFERROR(STDEVA(D28:H28),#N/A) -> 4.7644517 | Q28: =MEDIAN(D28:H28) -> 24 | R28: =MAX(J28:O28) -> 36 | S28: =100*(R28-Q28)/Q28 -> 50
B29: Healthy | C29: HP-38 | D29: 32 | E29: 25 | F29: 23 | G29: 25 | H29: 23 | I29: 23 | J29: 39 | K29: 29 | L29: 21 | M29: 26 | N29: 27 | O29: 22 | P29: =IFERROR(STDEVA(D29:H29),#N/A) -> 3.7148351 | Q29: =MEDIAN(D29:H29) -> 25 | R29: =MAX(J29:O29) -> 39 | S29: =100*(R29-Q29)/Q29 -> 56
P30: Mean of median | Q30: =AVERAGE(Q23:Q29) -> 34.285714 | R30: =AVERAGE(R23:R29) -> 49.857143 | S30: =AVERAGE(S23:S29) -> 55.628823
P31: SD | Q31: =STDEVA(Q19:Q29) -> 10.827654 | R31: =STDEVA(R19:R29) -> 10.636863 | S31: =STDEVA(S23:S29) -> 50.815635
P32: COV | Q32: =Q31/Q30 -> 0.31580658 | R32: =R31/R30 -> 0.21334682 | S32: =S31/S30 -> 0.91347671
O33: Number of scans per subject | P33: 5 | Q33: <-insert correct numbers before the analysis | AE33: Number of scans per subject | AF33: 5 | AG33: <-insert correct numbers before the analysis | AT33: Number of scans per subject | AU33: 5 | AV33: <-insert correct numbers before the analysis | BI33: Number of scans per subject | BJ33: 5 | BK33: <-insert correct numbers before the analysis
O34: Number of subjects | P34: 7 | Q34: <-insert correct numbers before the analysis | AE34: Number of subjects | AF34: 10 | AG34: <-insert correct numbers before the analysis | AT34: Number of subjects | AU34: 10 | AV34: <-insert correct numbers before the analysis | BI34: Number of subjects | BJ34: 10 | BK34: <-insert correct numbers before the analysis
O35: Within SD | P35: =SQRT(AVERAGE(P23:P32)) -> 2.4534685 | AE35: Within SD | AF35: =SQRT(AVERAGE(AF23:AF32)) -> #DIV/0! | AT35: Within SD | AU35: =SQRT(AVERAGE(AU23:AU32)) -> #DIV/0! | BI35: Within SD | BJ35: =SQRT(AVERAGE(BJ23:BJ32)) -> #DIV/0!
O36: CR | P36: =2.77*P35 -> 6.7961076 | AE36: CR | AF36: =2.77*AF35 -> #DIV/0! | AT36: CR | AU36: =2.77*AU35 -> #DIV/0! | BI36: CR | BJ36: =2.77*BJ35 -> #DIV/0!
O37: CI_A | P37: =P36-(1.96*(P35/(SQRT(2*P34*(P33-1))))) -> 6.1535049 | AE37: CI_A | AF37: =AF36-(1.96*(AF35/(SQRT(2*AF34*(AF33-1))))) -> #DIV/0! | AT37: CI_A | AU37: =AU36-(1.96*(AU35/(SQRT(2*AU34*(AU33-1))))) -> #DIV/0! | BI37: CI_A | BJ37: =BJ36-(1.96*(BJ35/(SQRT(2*BJ34*(BJ33-1))))) -> #DIV/0!
O38: CI_B | P38: =P36+(1.96*(P35/(SQRT(2*P34*(P33-1))))) -> 7.4387103 | AE38: CI_B | AF38: =AF36+(1.96*(AF35/(SQRT(2*AF34*(AF33-1))))) -> #DIV/0! | AT38: CI_B | AU38: =AU36+(1.96*(AU35/(SQRT(2*AU34*(AU33-1))))) -> #DIV/0! | BI38: CI_B | BJ38: =BJ36+(1.96*(BJ35/(SQRT(2*BJ34*(BJ33-1))))) -> #DIV/0!
A40: 40-49 | B40: Healthy | C40: HP-12 | D40: 37 | E40: 42 | F40: 41 | G40: 45 | H40: 41 | I40: 20 | J40: 55 | K40: 49 | L40: 50 | M40: 47 | P40: =IFERROR(STDEVA(D40:H40),#N/A) -> 2.8635642 | Q40: =MEDIAN(D40:H40) -> 41 | R40: =MAX(J40:O40) -> 55 | S40: =100*(R40-Q40)/Q40 -> 34.146341
B41: Healthy | C41: HP-15 | D41: 25 | E41: 20 | F41: 18 | G41: 19 | H41: 21 | I41: 16 | J41: 54 | K41: 51 | L41: 39 | M41: 33 | P41: =IFERROR(STDEVA(D41:H41),#N/A) -> 2.7018512 | Q41: =MEDIAN(D41:H41) -> 20 | R41: =MAX(J41:O41) -> 54 | S41: =100*(R41-Q41)/Q41 -> 170
B42: Healthy | C42: HP-20 | D42: 27 | E42: 27 | F42: 26 | G42: 32 | H42: 32 | I42: 26 | J42: 49 | K42: 43 | L42: 39 | M42: 37 | N42: 31 | O42: 43 | P42: =IFERROR(STDEVA(D42:H42),#N/A) -> 2.9495762 | Q42: =MEDIAN(D42:H42) -> 27 | R42: =MAX(J42:O42) -> 49 | S42: =100*(R42-Q42)/Q42 -> 81.481481 | T42: 28 | U42: 36 | V42: 38 | W42: 39 | X42: 44 | Y42: 20 | Z42: 49 | AA42: 45 | AB42: 45 | AC42: 41 | AD42: 38 | AE42: 38
...

Sheet Vessel Length Density
D1: SESSION 1 | P1: Coefficient of repeatibility analysis from the baseline scans | T1: SESSION 2 | AF1: Coefficient of repeatibility analysis from the baseline scans | AI1: SESSION 3 | AU1: Coefficient of repeatibility analysis from the baseline scans | AX1: SESSION 4 | BJ1: Coefficient of repeatibility analysis from the baseline scans
D2: Baseline | I2: Ischemia | J2: PORH | Q2: Median value of 5 measures | R2: MAX PORH | S2: Absolute diff between PORH and Median | T2: Baseline | Y2: Ischemia | Z2: PORH | AI2: Baseline | AN2: Ischemia | AO2: PORH | AX2: Baseline | BC2: Ischemia | BD2: PORH
A3: Age group | B3: Health/disease | C3: Participant ID | D3: Scan 1 | E3: Scan 2 | F3: Scan 3 | G3: Scan 4 | H3: Scan 5 | I3: Scan 6 | J3: Scan 7 | K3: Scan 8 | L3: Scan 9 | M3: Scan 10 | N3: Scan 11 | O3: Scan 12 | P3: Variance of (SD) | T3: ` | U3: Scan 2 | V3: Scan 3 | W3: Scan 4 | X3: Scan 5 | Y3: Scan 6 | Z3: Scan 7 | AA3: Scan 8 | AB3: Scan 9 | AC3: Scan 10 | AD3: Scan 11 | AE3: Scan 12 | AF3: Variance of (SD) | AI3: Scan 1 | AJ3: Scan 2 | AK3: Scan 3 | AL3: Scan 4 | AM3: Scan 5 | AN3: Scan 6 | AO3: Scan 7 | AP3: Scan 8 | AQ3: Scan 9 | AR3: Scan 10 | AS3: Scan 11 | AT3: Scan 12 | AU3: Variance of (SD) | AX3: Scan 1 | AY3: Scan 2 | AZ3: Scan 3 | BA3: Scan 4 | BB3: Scan 5 | BC3: Scan 6 | BD3: Scan 7 | BE3: Scan 8 | BF3: Scan 9 | BG3: Scan 10 | BH3: Scan 11 | BI3: Scan 12 | BJ3: Variance of (SD)
B4: Healthy | C4: HP-03 | D4: 1.3 | E4: 1.67 | F4: 1.35 | G4: 1.58 | H4: 1.49 | I4: 0.61 | J4: 2.33 | K4: 1.93 | L4: 2.13 | M4: 2.07 | P4: =IFERROR(STDEVA(D4:H4),#N/A) -> 0.15449919 | Q4: =MEDIAN(D4:H4) -> 1.49 | R4: =MAX(J4:O4) -> 2.33 | S4: =100*(R4-Q4)/Q4 -> 56.375839 | AF4: =IFERROR(STDEVA(T4:X4),#N/A) -> #N/A | AU4: =IFERROR(STDEVA(AI4:AM4),#N/A) -> #N/A | BJ4: =IFERROR(STDEVA(AX4:BB4),#N/A) -> #N/A
B5: Healthy | C5: HP-05 | D5: 2.46 | E5: 2.29 | F5: 2.55 | G5: 2.74 | H5: 2.82 | I5: 1.17 | J5: 3.13 | K5: 3.1 | L5: 3.23 | M5: 3.33 | P5: =IFERROR(STDEVA(D5:H5),#N/A) -> 0.21347131 | Q5: =MEDIAN(D5:H5) -> 2.55 | R5: =MAX(J5:O5) -> 3.33 | S5: =100*(R5-Q5)/Q5 -> 30.588235 | AF5: =IFERROR(STDEVA(T5:X5),#N/A) -> #N/A | AU5: =IFERROR(STDEVA(AI5:AM5),#N/A) -> #N/A | BJ5: =IFERROR(STDEVA(AX5:BB5),#N/A) -> #N/A
B6: Healthy | C6: HP-06 | D6: 2.54 | E6: 2.59 | F6: 2.35 | G6: 2.59 | H6: 2.71 | I6: 1.48 | J6: 3.45 | K6: 3.37 | L6: 3.34 | M6: 3.15 | P6: =IFERROR(STDEVA(D6:H6),#N/A) -> 0.1310725 | Q6: =MEDIAN(D6:H6) -> 2.59 | R6: =MAX(J6:O6) -> 3.45 | S6: =100*(R6-Q6)/Q6 -> 33.204633 | AF6: =IFERROR(STDEVA(T6:X6),#N/A) -> #N/A | AU6: =IFERROR(STDEVA(AI6:AM6),#N/A) -> #N/A | BJ6: =IFERROR(STDEVA(AX6:BB6),#N/A) -> #N/A
B7: Healthy | C7: HP-07 | D7: 2.03 | E7: 2.23 | F7: 2.34 | G7: 2.23 | H7: 2.49 | I7: 0.86 | J7: 3 | K7: 3.05 | L7: 2.63 | M7: 2.64 | P7: =IFERROR(STDEVA(D7:H7),#N/A) -> 0.16876018 | Q7: =MEDIAN(D7:H7) -> 2.23 | R7: =MAX(J7:O7) -> 3.05 | S7: =100*(R7-Q7)/Q7 -> 36.7713 | AF7: =IFERROR(STDEVA(T7:X7),#N/A) -> #N/A | AU7: =IFERROR(STDEVA(AI7:AM7),#N/A) -> #N/A | BJ7: =IFERROR(STDEVA(AX7:BB7),#N/A) -> #N/A
B8: Healthy | C8: HP-09 | D8: 1.49 | E8: 2.05 | F8: 2.38 | G8: 2.42 | H8: 1.99 | I8: 1 | J8: 3.36 | K8: 3.28 | L8: 3.11 | M8: 2.97 | P8: =IFERROR(STDEVA(D8:H8),#N/A) -> 0.37473991 | Q8: =MEDIAN(D8:H8) -> 2.05 | R8: =MAX(J8:O8) -> 3.36 | S8: =100*(R8-Q8)/Q8 -> 63.902439 | AF8: =IFERROR(STDEVA(T8:X8),#N/A) -> #N/A | AU8: =IFERROR(STDEVA(AI8:AM8),#N/A) -> #N/A | BJ8: =IFERROR(STDEVA(AX8:BB8),#N/A) -> #N/A
B9: Healthy | C9: HP-10 | D9: 1.86 | E9: 1.88 | F9: 1.83 | G9: 1.91 | H9: 1.56 | I9: 2.03 | J9: 2.91 | K9: 2.38 | L9: 1.99 | M9: 2.31 | P9: =IFERROR(STDEVA(D9:H9),#N/A) -> 0.14166863 | Q9: =MEDIAN(D9:H9) -> 1.86 | R9: =MAX(J9:O9) -> 2.91 | S9: =100*(R9-Q9)/Q9 -> 56.451613 | AF9: =IFERROR(STDEVA(T9:X9),#N/A) -> #N/A | AU9: =IFERROR(STDEVA(AI9:AM9),#N/A) -> #N/A | BJ9: =IFERROR(STDEVA(AX9:BB9),#N/A) -> #N/A
B10: Healthy | C10: HP-11 | D10: 1.5 | E10: 2.18 | F10: 1.35 | G10: 1.53 | H10: 1.46 | I10: 1.58 | J10: 2.83 | K10: 3.05 | L10: 2.74 | M10: 2.27 | P10: =IFERROR(STDEVA(D10:H10),#N/A) -> 0.32913523 | Q10: =MEDIAN(D10:H10) -> 1.5 | R10: =MAX(J10:O10) -> 3.05 | S10: =100*(R10-Q10)/Q10 -> 103.33333 | AF10: =IFERROR(STDEVA(T10:X10),#N/A) -> #N/A | AU10: =IFERROR(STDEVA(AI10:AM10),#N/A) -> #N/A | BJ10: =IFERROR(STDEVA(AX10:BB10),#N/A) -> #N/A
B11: Healthy | C11: HP-18 | D11: 1.48 | E11: 1.62 | F11: 3.06 | G11: 3.06 | H11: 2.89 | I11: 0.89 | J11: 3.35 | K11: 3.18 | L11: 3.26 | M11: 3.22 | P11: =IFERROR(STDEVA(D11:H11),#N/A) -> 0.80057479 | Q11: =MEDIAN(D11:H11) -> 2.89 | R11: =MAX(J11:O11) -> 3.35 | S11: =100*(R11-Q11)/Q11 -> 15.916955 | AF11: =IFERROR(STDEVA(T11:X11),#N/A) -> #N/A | AU11: =IFERROR(STDEVA(AI11:AM11),#N/A) -> #N/A | BJ11: =IFERROR(STDEVA(AX11:BB11),#N/A) -> #N/A
B12: Healthy | C12: HP-24 | D12: 1.7 | E12: 2.07 | F12: 2.14 | G12: 2.18 | H12: 1.94 | I12: 1.37 | J12: 2.37 | K12: 2.19 | L12: 2.06 | M12: 2.39 | N12: 2.04 | O12: 1.74 | P12: =IFERROR(STDEVA(D12:H12),#N/A) -> 0.19385562 | Q12: =MEDIAN(D12:H12) -> 2.07 | R12: =MAX(J12:O12) -> 2.39 | S12: =100*(R12-Q12)/Q12 -> 15.458937 | AF12: =IFERROR(STDEVA(T12:X12),#N/A) -> #N/A | AU12: =IFERROR(STDEVA(AI12:AM12),#N/A) -> #N/A | BJ12: =IFERROR(STDEVA(AX12:BB12),#N/A) -> #N/A
P13: Mean of median | Q13: =AVERAGE(Q4:Q12) -> 2.1366667 | R13: =AVERAGE(R4:R12) -> 3.0244444 | S13: =AVERAGE(S4:S12) -> 45.778143 | AF13: =IFERROR(STDEVA(T13:X13),#N/A) -> #N/A | AU13: =IFERROR(STDEVA(AI13:AM13),#N/A) -> #N/A | BJ13: =IFERROR(STDEVA(AX13:BB13),#N/A) -> #N/A
P14: SD | Q14: =STDEVA(Q4:Q12) -> 0.48277842 | R14: =STDEVA(R4:R12) -> 0.41716637 | S14: =STDEVA(S4:S12) -> 27.722325 | AF14: =IFERROR(STDEVA(T14:X14),#N/A) -> #N/A | AU14: =IFERROR(STDEVA(AI14:AM14),#N/A) -> #N/A | BJ14: =IFERROR(STDEVA(AX14:BB14),#N/A) -> #N/A
P15: COV | Q15: =Q14/Q13 -> 0.22594934 | R15: =R14/R13 -> 0.13793157 | S15: =S14/S13 -> 0.60557995 | AF15: =IFERROR(STDEVA(T15:X15),#N/A) -> #N/A | AU15: =IFERROR(STDEVA(AI15:AM15),#N/A) -> #N/A | BJ15: =IFERROR(STDEVA(AX15:BB15),#N/A) -> #N/A
O16: Number of scans per subject | P16: 5 | Q16: <-insert correct numbers before the analysis | AE16: Number of scans per subject | AF16: 5 | AG16: <-insert correct numbers before the analysis | AT16: Number of scans per subject | AU16: 5 | AV16: <-insert correct numbers before the analysis | BI16: Number of scans per subject | BJ16: 5 | BK16: <-insert correct numbers before the analysis
O17: Number of subjects | P17: 9 | Q17: <-insert correct numbers before the analysis | AE17: Number of subjects | AF17: 10 | AG17: <-insert correct numbers before the analysis | AT17: Number of subjects | AU17: 10 | AV17: <-insert correct numbers before the analysis | BI17: Number of subjects | BJ17: 10 | BK17: <-insert correct numbers before the analysis
O18: Within SD | P18: =SQRT(AVERAGE(P4:P12)) -> 0.52786545 | AE18: Within SD | AF18: =SQRT(AVERAGE(AF4:AF15)) -> #N/A | AT18: Within SD | AU18: =SQRT(AVERAGE(AU4:AU15)) -> #N/A | BI18: Within SD | BJ18: =SQRT(AVERAGE(BJ4:BJ15)) -> #N/A
O19: CR | P19: =2.77*P18 -> 1.4621873 | AE19: CR | AF19: =2.77*AF18 -> #N/A | AT19: CR | AU19: =2.77*AU18 -> #N/A | BI19: CR | BJ19: =2.77*BJ18 -> #N/A
O20: CI_A | P20: =P19-(1.96*(P18/(SQRT(2*P17*(P16-1))))) -> 1.3402566 | AE20: CI_A | AF20: =AF19-(1.96*(AF18/(SQRT(2*AF17*(AF16-1))))) -> #N/A | AT20: CI_A | AU20: =AU19-(1.96*(AU18/(SQRT(2*AU17*(AU16-1))))) -> #N/A | BI20: CI_A | BJ20: =BJ19-(1.96*(BJ18/(SQRT(2*BJ17*(BJ16-1))))) -> #N/A
O21: CI_B | P21: =P19+(1.96*(P18/(SQRT(2*P17*(P16-1))))) -> 1.584118 | AE21: CI_B | AF21: =AF19+(1.96*(AF18/(SQRT(2*AF17*(AF16-1))))) -> #N/A | AT21: CI_B | AU21: =AU19+(1.96*(AU18/(SQRT(2*AU17*(AU16-1))))) -> #N/A | BI21: CI_B | BJ21: =BJ19+(1.96*(BJ18/(SQRT(2*BJ17*(BJ16-1))))) -> #N/A
A23: 30-39 | B23: Healthy | C23: HP-04 | D23: 2.06 | E23: 1.86 | F23: 2.16 | G23: 2.38 | H23: 2.63 | I23: 0.61 | J23: 3.02 | K23: 2.61 | L23: 2.64 | M23: 2.7 | P23: =IFERROR(STDEVA(D23:H23),#N/A) -> 0.29685013 | Q23: =MEDIAN(D23:H23) -> 2.16 | R23: =MAX(J23:O23) -> 3.02 | S23: =100*(R23-Q23)/Q23 -> 39.814815
B24: Healthy | C24: HP-08 | D24: 1.65 | E24: 2.59 | F24: 2.5 | G24: 2.4 | H24: 2.16 | I24: 0.92 | J24: 3.28 | K24: 3.27 | L24: 3.18 | M24: 3.17 | P24: =IFERROR(STDEVA(D24:H24),#N/A) -> 0.37689521 | Q24: =MEDIAN(D24:H24) -> 2.4 | R24: =MAX(J24:O24) -> 3.28 | S24: =100*(R24-Q24)/Q24 -> 36.666667
B25: Healthy | C25: HP-19 | D25: 0.71 | E25: 1.28 | F25: 0.81 | G25: 1.34 | H25: 1.82 | I25: 0.69 | J25: 2.6 | K25: 2.64 | L25: 3.04 | M25: 2.09 | P25: =IFERROR(STDEVA(D25:H25),#N/A) -> 0.44785042 | Q25: =MEDIAN(D25:H25) -> 1.28 | R25: =MAX(J25:O25) -> 3.04 | S25: =100*(R25-Q25)/Q25 -> 137.5
B26: Healthy | C26: HP-21 | D26: 2.03 | E26: 2.28 | F26: 2.61 | G26: 2.37 | H26: 2.5 | I26: 0.78 | J26: 2.81 | K26: 2.46 | L26: 2.47 | M26: 2.41 | N26: 2.51 | O26: 2.48 | P26: =IFERROR(STDEVA(D26:H26),#N/A) -> 0.22219361 | Q26: =MEDIAN(D26:H26) -> 2.37 | R26: =MAX(J26:O26) -> 2.81 | S26: =100*(R26-Q26)/Q26 -> 18.565401 | T26: 2.03 | U26: 2.06 | V26: 1.87 | W26: 1.81 | X26: 2.32 | Y26: 1.1 | Z26: 2.6 | AA26: 2.63 | AB26: 2.62 | AC26: 2.47 | AD26: 2.59 | AE26: 2.61 | AI26: 2.35 | AJ26: 2.66 | AK26: 2.52 | AL26: 2.24 | AM26: 2.29 | AN26: 1.46 | AO26: 2.35 | AP26: 2.52 | AQ26: 2.66 | AR26: 2.42 | AS26: 2.67 | AT26: 2.59 | AX26: 2.46 | AY26: 2.36 | AZ26: 2.41 | BA26: 2.51 | BB26: 2.6 | BC26: 0.94 | BD26: 2.67 | BE26: 2.58 | BF26: 2.65 | BG26: 2.68 | BH26: 2.71 | BI26: 2.68
B27: Healthy | C27: HP-22 | D27: 2.46 | E27: 1.28 | F27: 2.75 | G27: 2.8 | H27: 2.73 | I27: 1.33 | J27: 2.13 | K27: 1.84 | L27: 1.9 | M27: 1.76 | N27: 2.29 | O27: 2.06 | P27: =IFERROR(STDEVA(D27:H27),#N/A) -> 0.64212927 | Q27: =MEDIAN(D27:H27) -> 2.73 | R27: =MAX(J27:O27) -> 2.29 | S27: =100*(R27-Q27)/Q27 -> -16.117216
B28: Healthy | C28: HP-30 | D28: 0.93 | E28: 1.49 | F28: 1.68 | G28: 1.73 | H28: 1.38 | I28: 1.5 | J28: 1.28 | K28: 2.07 | L28: 2.28 | M28: 2.21 | N28: 2.24 | O28: 2.02 | P28: =IFERROR(STDEVA(D28:H28),#N/A) -> 0.31932742 | Q28: =MEDIAN(D28:H28) -> 1.49 | R28: =MAX(J28:O28) -> 2.28 | S28: =100*(R28-Q28)/Q28 -> 53.020134
B29: Healthy | C29: HP-38 | D29: 2.12 | E29: 1.52 | F29: 1.27 | G29: 1.48 | H29: 1.32 | I29: 1.36 | J29: 2.2 | K29: 1.66 | L29: 1.16 | M29: 1.49 | N29: 1.63 | O29: 1.26 | P29: =IFERROR(STDEVA(D29:H29),#N/A) -> 0.33973519 | Q29: =MEDIAN(D29:H29) -> 1.48 | R29: =MAX(J29:O29) -> 2.2 | S29: =100*(R29-Q29)/Q29 -> 48.648649
P30: Mean of median | Q30: =AVERAGE(Q23:Q29) -> 1.9871429 | R30: =AVERAGE(R21:R29) -> 2.7028571 | S30: =AVERAGE(S23:S29) -> 45.442636
P31: SD | Q31: =STDEVA(Q19:Q29) -> 0.56319666 | R31: =STDEVA(R21:R29) -> 0.43987552 | S31: =STDEVA(S23:S29) -> 46.838279
P32: COV | Q32: =Q31/Q30 -> 0.28342032 | R32: =R31/R30 -> 0.16274464 | S32: =S31/S30 -> 1.0307122
O33: Number of scans per subject | P33: 5 | Q33: <-insert correct numbers before the analysis | AE33: Number of scans per subject | AF33: 5 | AG33: <-insert correct numbers before the analysis | AT33: Number of scans per subject | AU33: 5 | AV33: <-insert correct numbers before the analysis | BI33: Number of scans per subject | BJ33: 5 | BK33: <-insert correct numbers before the analysis
O34: Number of subjects | P34: 7 | Q34: <-insert correct numbers before the analysis | AE34: Number of subjects | AF34: 10 | AG34: <-insert correct numbers before the analysis | AT34: Number of subjects | AU34: 10 | AV34: <-insert correct numbers before the analysis | BI34: Number of subjects | BJ34: 10 | BK34: <-insert correct numbers before the analysis
O35: Within SD | P35: =SQRT(AVERAGE(P23:P32)) -> 0.61469868 | AE35: Within SD | AF35: =SQRT(AVERAGE(AF23:AF32)) -> #DIV/0! | AT35: Within SD | AU35: =SQRT(AVERAGE(AU23:AU32)) -> #DIV/0! | BI35: Within SD | BJ35: =SQRT(AVERAGE(BJ23:BJ32)) -> #DIV/0!
O36: CR | P36: =2.77*P35 -> 1.7027153 | AE36: CR | AF36: =2.77*AF35 -> #DIV/0! | AT36: CR | AU36: =2.77*AU35 -> #DIV/0! | BI36: CR | BJ36: =2.77*BJ35 -> #DIV/0!
O37: CI_A | P37: =P36-(1.96*(P35/(SQRT(2*P34*(P33-1))))) -> 1.5417159 | AE37: CI_A | AF37: =AF36-(1.96*(AF35/(SQRT(2*AF34*(AF33-1))))) -> #DIV/0! | AT37: CI_A | AU37: =AU36-(1.96*(AU35/(SQRT(2*AU34*(AU33-1))))) -> #DIV/0! | BI37: CI_A | BJ37: =BJ36-(1.96*(BJ35/(SQRT(2*BJ34*(BJ33-1))))) -> #DIV/0!
O38: CI_B | P38: =P36+(1.96*(P35/(SQRT(2*P34*(P33-1))))) -> 1.8637148 | AE38: CI_B | AF38: =AF36+(1.96*(AF35/(SQRT(2*AF34*(AF33-1))))) -> #DIV/0! | AT38: CI_B | AU38: =AU36+(1.96*(AU35/(SQRT(2*AU34*(AU33-1))))) -> #DIV/0! | BI38: CI_B | BJ38: =BJ36+(1.96*(BJ35/(SQRT(2*BJ34*(BJ33-1))))) -> #DIV/0!
A40: 40-49 | B40: Healthy | C40: HP-12 | D40: 2.21 | E40: 2.55 | F40: 2.48 | G40: 2.73 | H40: 2.51 | I40: 1.02 | J40: 3.04 | K40: 2.82 | L40: 2.94 | M40: 2.78 | P40: =IFERROR(STDEVA(D40:H40),#N/A) -> 0.18702941 | Q40: =MEDIAN(D40:H40) -> 2.51 | R40: =MAX(J40:O40) -> 3.04 | S40: =100*(R40-Q40)/Q40 -> 21.115538
B41: Healthy | C41: HP-15 | D41: 1.47 | E41: 1.13 | F41: 0.94 | G41: 0.9 | H41: 1.18 | I41: 0.86 | J41: 3.29 | K41: 3.02 | L41: 2.4 | M41: 2 | P41: =IFERROR(STDEVA(D41:H41),#N/A) -> 0.2274423 | Q41: =MEDIAN(D41:H41) -> 1.13 | R41: =MAX(J41:O41) -> 3.29 | S41: =100*(R41-Q41)/Q41 -> 191.15044
B42: Healthy | C42: HP-20 | D42: 1.54 | E42: 1.6 | F42: 1.47 | G42: 1.97 | H42: 1.91 | I42: 1.61 | J42: 2.66 | K42: 2.42 | L42: 2.27 | M42: 2.23 | N42: 1.79 | O42: 2.47 | P42: =IFERROR(STDEVA(D42:H42),#N/A) -> 0.22664951 | Q42: =MEDIAN(D42:H42) -> 1.6 | R42: =MAX(J42:O42) -> 2.66 | S42: =100*(R42-Q42)/Q42 -> 66.25 | T42: 2.17 | U42: 1.59 | V42: 1.79 | W42: 1.45 | X42: 1.73 | Y42: 1.03 | Z42: 2.63 | AA42: 2.61 | AB42: 2.47 | AC42: 2.21 | AD42: 1.96 | AE42: 2.16 | AI42: 1.59 | AJ42: 2.05 | AK42: 2.21 | AL42: 2.24 | AM42: 2.45 | AN42: 1.16 | AO42: 2.53 | AP42: 2.36 | AQ42: 2.35 | AR42: 2.26 | AS42: 2.16 | AT42: 2.13 | AX42: 1.72 | AY42: 1.81 | AZ42: 2.22 | BA42: 2.26 | BB42: 2.21 | BC42: 1.21 | BD42: 2.56 | BE42: 2.56 | BF42: 2.37 | BG42: 2.29 | BH42: 2.34 | BI42: 2.46
...

Sheet Branchpoint density
D1: SESSION 1 | P1: Coefficient of repeatibility analysis from the baseline scans | T1: SESSION 2 | AF1: Coefficient of repeatibility analysis from the baseline scans | AI1: SESSION 3 | AU1: Coefficient of repeatibility analysis from the baseline scans | AX1: SESSION 4 | BJ1: Coefficient of repeatibility analysis from the baseline scans
D2: Baseline | I2: Ischemia | J2: PORH | Q2: Median value of 5 measures | R2: MAX PORH | S2: Absolute diff between PORH and Median | T2: Baseline | Y2: Ischemia | Z2: PORH | AI2: Baseline | AN2: Ischemia | AO2: PORH | AX2: Baseline | BC2: Ischemia | BD2: PORH
A3: Age group | B3: Health/disease | C3: Participant ID | D3: Scan 1 | E3: Scan 2 | F3: Scan 3 | G3: Scan 4 | H3: Scan 5 | I3: Scan 6 | J3: Scan 7 | K3: Scan 8 | L3: Scan 9 | M3: Scan 10 | N3: Scan 11 | O3: Scan 12 | P3: Variance of (SD) | T3: Scan 1 | U3: Scan 2 | V3: Scan 3 | W3: Scan 4 | X3: Scan 5 | Y3: Scan 6 | Z3: Scan 7 | AA3: Scan 8 | AB3: Scan 9 | AC3: Scan 10 | AD3: Scan 11 | AE3: Scan 12 | AF3: Variance of (SD) | AI3: Scan 1 | AJ3: Scan 2 | AK3: Scan 3 | AL3: Scan 4 | AM3: Scan 5 | AN3: Scan 6 | AO3: Scan 7 | AP3: Scan 8 | AQ3: Scan 9 | AR3: Scan 10 | AS3: Scan 11 | AT3: Scan 12 | AU3: Variance of (SD) | AX3: Scan 1 | AY3: Scan 2 | AZ3: Scan 3 | BA3: Scan 4 | BB3: Scan 5 | BC3: Scan 6 | BD3: Scan 7 | BE3: Scan 8 | BF3: Scan 9 | BG3: Scan 10 | BH3: Scan 11 | BI3: Scan 12 | BJ3: Variance of (SD)
B4: Healthy | C4: HP-03 | D4: 1.33 | E4: 1.61 | F4: 1.47 | G4: 1.42 | H4: 1.35 | I4: 0.89 | J4: 2.45 | K4: 1.9 | L4: 1.99 | M4: 2.04 | P4: =IFERROR(STDEVA(D4:H4),#N/A) -> 0.1121606 | Q4: =MEDIAN(D4:H4) -> 1.42 | R4: =MAX(J4:O4) -> 2.45 | S4: =100*(R4-Q4)/Q4 -> 72.535211 | AF4: =IFERROR(STDEVA(T4:X4),#N/A) -> #N/A | AU4: =IFERROR(STDEVA(AI4:AM4),#N/A) -> #N/A | BJ4: =IFERROR(STDEVA(AX4:BB4),#N/A) -> #N/A
B5: Healthy | C5: HP-05 | D5: 2.23 | E5: 2.46 | F5: 2.82 | G5: 2.9 | H5: 2.9 | I5: 1.06 | J5: 3.56 | K5: 3.31 | L5: 3.6 | M5: 3.23 | P5: =IFERROR(STDEVA(D5:H5),#N/A) -> 0.3023574 | Q5: =MEDIAN(D5:H5) -> 2.82 | R5: =MAX(J5:O5) -> 3.6 | S5: =100*(R5-Q5)/Q5 -> 27.659574 | AF5: =IFERROR(STDEVA(T5:X5),#N/A) -> #N/A | AU5: =IFERROR(STDEVA(AI5:AM5),#N/A) -> #N/A | BJ5: =IFERROR(STDEVA(AX5:BB5),#N/A) -> #N/A
B6: Healthy | C6: HP-06 | D6: 2.63 | E6: 2.71 | F6: 2.75 | G6: 2.68 | H6: 2.66 | I6: 0.95 | J6: 3.79 | K6: 4.23 | L6: 3.83 | M6: 3.52 | P6: =IFERROR(STDEVA(D6:H6),#N/A) -> 0.046151923 | Q6: =MEDIAN(D6:H6) -> 2.68 | R6: =MAX(J6:O6) -> 4.23 | S6: =100*(R6-Q6)/Q6 -> 57.835821 | AF6: =IFERROR(STDEVA(T6:X6),#N/A) -> #N/A | AU6: =IFERROR(STDEVA(AI6:AM6),#N/A) -> #N/A | BJ6: =IFERROR(STDEVA(AX6:BB6),#N/A) -> #N/A
B7: Healthy | C7: HP-07 | D7: 1.66 | E7: 1.85 | F7: 2.01 | G7: 1.94 | H7: 2.07 | I7: 0.68 | J7: 3.44 | K7: 3.05 | L7: 2.58 | M7: 2.93 | P7: =IFERROR(STDEVA(D7:H7),#N/A) -> 0.16009372 | Q7: =MEDIAN(D7:H7) -> 1.94 | R7: =MAX(J7:O7) -> 3.44 | S7: =100*(R7-Q7)/Q7 -> 77.319588 | AF7: =IFERROR(STDEVA(T7:X7),#N/A) -> #N/A | AU7: =IFERROR(STDEVA(AI7:AM7),#N/A) -> #N/A | BJ7: =IFERROR(STDEVA(AX7:BB7),#N/A) -> #N/A
B8: Healthy | C8: HP-09 | D8: 1.4 | E8: 1.82 | F8: 2.05 | G8: 2.09 | H8: 1.7 | I8: 1.19 | J8: 4.72 | K8: 3.74 | L8: 3.3 | M8: 2.85 | P8: =IFERROR(STDEVA(D8:H8),#N/A) -> 0.28119388 | Q8: =MEDIAN(D8:H8) -> 1.82 | R8: =MAX(J8:O8) -> 4.72 | S8: =100*(R8-Q8)/Q8 -> 159.34066 | AF8: =IFERROR(STDEVA(T8:X8),#N/A) -> #N/A | AU8: =IFERROR(STDEVA(AI8:AM8),#N/A) -> #N/A | BJ8: =IFERROR(STDEVA(AX8:BB8),#N/A) -> #N/A
B9: Healthy | C9: HP-10 | D9: 1.73 | E9: 1.98 | F9: 1.67 | G9: 1.82 | H9: 1.65 | I9: 1.14 | J9: 3.23 | K9: 2.15 | L9: 1.6 | M9: 1.75 | P9: =IFERROR(STDEVA(D9:H9),#N/A) -> 0.13472194 | Q9: =MEDIAN(D9:H9) -> 1.73 | R9: =MAX(J9:O9) -> 3.23 | S9: =100*(R9-Q9)/Q9 -> 86.705202 | AF9: =IFERROR(STDEVA(T9:X9),#N/A) -> #N/A | AU9: =IFERROR(STDEVA(AI9:AM9),#N/A) -> #N/A | BJ9: =IFERROR(STDEVA(AX9:BB9),#N/A) -> #N/A
B10: Healthy | C10: HP-11 | D10: 1.24 | E10: 1.83 | F10: 1.2 | G10: 1.37 | H10: 1.13 | I10: 1.5 | J10: 2.78 | K10: 3.17 | L10: 2.68 | M10: 1.89 | P10: =IFERROR(STDEVA(D10:H10),#N/A) -> 0.28005357 | Q10: =MEDIAN(D10:H10) -> 1.24 | R10: =MAX(J10:O10) -> 3.17 | S10: =100*(R10-Q10)/Q10 -> 155.64516 | AF10: =IFERROR(STDEVA(T10:X10),#N/A) -> #N/A | AU10: =IFERROR(STDEVA(AI10:AM10),#N/A) -> #N/A | BJ10: =IFERROR(STDEVA(AX10:BB10),#N/A) -> #N/A
B11: Healthy | C11: HP-18 | D11: 1.05 | E11: 1.57 | F11: 3.15 | G11: 3.52 | H11: 2.78 | I11: 0.72 | J11: 4.15 | K11: 4.87 | L11: 4.53 | M11: 4.56 | P11: =IFERROR(STDEVA(D11:H11),#N/A) -> 1.0573221 | Q11: =MEDIAN(D11:H11) -> 2.78 | R11: =MAX(J11:O11) -> 4.87 | S11: =100*(R11-Q11)/Q11 -> 75.179856 | AF11: =IFERROR(STDEVA(T11:X11),#N/A) -> #N/A | AU11: =IFERROR(STDEVA(AI11:AM11),#N/A) -> #N/A | BJ11: =IFERROR(STDEVA(AX11:BB11),#N/A) -> #N/A
B12: Healthy | C12: HP-24 | D12: 2.52 | E12: 2.82 | F12: 2.85 | G12: 2.67 | H12: 2.46 | I12: 1.75 | J12: 2.94 | K12: 3.44 | L12: 2.92 | M12: 3.5 | N12: 2.78 | O12: 2.28 | P12: =IFERROR(STDEVA(D12:H12),#N/A) -> 0.1741551 | Q12: =MEDIAN(D12:H12) -> 2.67 | R12: =MAX(J12:O12) -> 3.5 | S12: =100*(R12-Q12)/Q12 -> 31.086142 | AF12: =IFERROR(STDEVA(T12:X12),#N/A) -> #N/A | AU12: =IFERROR(STDEVA(AI12:AM12),#N/A) -> #N/A | BJ12: =IFERROR(STDEVA(AX12:BB12),#N/A) -> #N/A
P13: Mean of median | Q13: =AVERAGE(Q4:Q12) -> 2.1222222 | R13: =AVERAGE(R4:R12) -> 3.69 | S13: =AVERAGE(S4:S12) -> 82.589691 | AF13: =IFERROR(STDEVA(T13:X13),#N/A) -> #N/A | AU13: =IFERROR(STDEVA(AI13:AM13),#N/A) -> #N/A | BJ13: =IFERROR(STDEVA(AX13:BB13),#N/A) -> #N/A
P14: SD | Q14: =STDEVA(Q4:Q12) -> 0.62053964 | R14: =STDEVA(R4:R12) -> 0.78032045 | S14: =STDEVA(S4:S12) -> 47.052112 | AF14: =IFERROR(STDEVA(T14:X14),#N/A) -> #N/A | AU14: =IFERROR(STDEVA(AI14:AM14),#N/A) -> #N/A | BJ14: =IFERROR(STDEVA(AX14:BB14),#N/A) -> #N/A
P15: COV | Q15: =Q14/Q13 -> 0.29240088 | R15: =R14/R13 -> 0.21146896 | S15: =S14/S13 -> 0.56970926 | AF15: =IFERROR(STDEVA(T15:X15),#N/A) -> #N/A | AU15: =IFERROR(STDEVA(AI15:AM15),#N/A) -> #N/A | BJ15: =IFERROR(STDEVA(AX15:BB15),#N/A) -> #N/A
O16: Number of scans per subject | P16: 5 | Q16: <-insert correct numbers before the analysis | AE16: Number of scans per subject | AF16: 5 | AG16: <-insert correct numbers before the analysis | AT16: Number of scans per subject | AU16: 5 | AV16: <-insert correct numbers before the analysis | BI16: Number of scans per subject | BJ16: 5 | BK16: <-insert correct numbers before the analysis
O17: Number of subjects | P17: 9 | Q17: <-insert correct numbers before the analysis | AE17: Number of subjects | AF17: 10 | AG17: <-insert correct numbers before the analysis | AT17: Number of subjects | AU17: 10 | AV17: <-insert correct numbers before the analysis | BI17: Number of subjects | BJ17: 10 | BK17: <-insert correct numbers before the analysis
O18: Within SD | P18: =SQRT(AVERAGE(P4:P12)) -> 0.53210381 | AE18: Within SD | AF18: =SQRT(AVERAGE(AF4:AF15)) -> #N/A | AT18: Within SD | AU18: =SQRT(AVERAGE(AU4:AU15)) -> #N/A | BI18: Within SD | BJ18: =SQRT(AVERAGE(BJ4:BJ15)) -> #N/A
O19: CR | P19: =2.77*P18 -> 1.4739276 | AE19: CR | AF19: =2.77*AF18 -> #N/A | AT19: CR | AU19: =2.77*AU18 -> #N/A | BI19: CR | BJ19: =2.77*BJ18 -> #N/A
O20: CI_A | P20: =P19-(1.96*(P18/(SQRT(2*P17*(P16-1))))) -> 1.3510179 | AE20: CI_A | AF20: =AF19-(1.96*(AF18/(SQRT(2*AF17*(AF16-1))))) -> #N/A | AT20: CI_A | AU20: =AU19-(1.96*(AU18/(SQRT(2*AU17*(AU16-1))))) -> #N/A | BI20: CI_A | BJ20: =BJ19-(1.96*(BJ18/(SQRT(2*BJ17*(BJ16-1))))) -> #N/A
O21: CI_B | P21: =P19+(1.96*(P18/(SQRT(2*P17*(P16-1))))) -> 1.5968373 | AE21: CI_B | AF21: =AF19+(1.96*(AF18/(SQRT(2*AF17*(AF16-1))))) -> #N/A | AT21: CI_B | AU21: =AU19+(1.96*(AU18/(SQRT(2*AU17*(AU16-1))))) -> #N/A | BI21: CI_B | BJ21: =BJ19+(1.96*(BJ18/(SQRT(2*BJ17*(BJ16-1))))) -> #N/A
A23: 30-39 | B23: Healthy | C23: HP-04 | D23: 2.05 | E23: 1.84 | F23: 1.81 | G23: 2.13 | H23: 2.46 | I23: 0.64 | J23: 2.95 | K23: 2.44 | L23: 2.08 | M23: 2.14 | P23: =IFERROR(STDEVA(D23:H23),#N/A) -> 0.2626214 | Q23: =MEDIAN(D23:H23) -> 2.05 | R23: =MAX(J23:O23) -> 2.95 | S23: =100*(R23-Q23)/Q23 -> 43.902439
B24: Healthy | C24: HP-08 | D24: 1.6 | E24: 2.19 | F24: 2.16 | G24: 2.11 | H24: 1.75 | I24: 1.04 | J24: 4.06 | K24: 3.58 | L24: 3.55 | M24: 3.1 | P24: =IFERROR(STDEVA(D24:H24),#N/A) -> 0.2688308 | Q24: =MEDIAN(D24:H24) -> 2.11 | R24: =MAX(J24:O24) -> 4.06 | S24: =100*(R24-Q24)/Q24 -> 92.417062
B25: Healthy | C25: HP-19 | D25: 1.08 | E25: 1.44 | F25: 0.95 | G25: 1.1 | H25: 1.56 | I25: 0.82 | J25: 2.25 | K25: 2.21 | L25: 3.26 | M25: 1.97 | P25: =IFERROR(STDEVA(D25:H25),#N/A) -> 0.2601538 | Q25: =MEDIAN(D25:H25) -> 1.1 | R25: =MAX(J25:O25) -> 3.26 | S25: =100*(R25-Q25)/Q25 -> 196.36364
B26: Healthy | C26: HP-21 | D26: 3.18 | E26: 3.42 | F26: 3.98 | G26: 3.17 | H26: 3.46 | I26: 1.52 | J26: 5.07 | K26: 3.68 | L26: 3.12 | M26: 3.05 | N26: 3.23 | O26: 3.31 | P26: =IFERROR(STDEVA(D26:H26),#N/A) -> 0.32896808 | Q26: =MEDIAN(D26:H26) -> 3.42 | R26: =MAX(J26:O26) -> 5.07 | S26: =100*(R26-Q26)/Q26 -> 48.245614 | T26: 2.96 | U26: 2.97 | V26: 2.88 | W26: 2.79 | X26: 3.37 | Y26: 1.18 | Z26: 5.66 | AA26: 5.7 | AB26: 4.61 | AC26: 4.2 | AD26: 4.02 | AE26: 3.99 | AI26: 2.93 | AJ26: 3.48 | AK26: 3.42 | AL26: 2.74 | AM26: 3 | AN26: 1.8 | AO26: 3.75 | AP26: 5.07 | AQ26: 5.19 | AR26: 3.58 | AS26: 4.11 | AT26: 3.76 | AX26: 3.92 | AY26: 3.78 | AZ26: 3.74 | BA26: 4.15 | BB26: 4.18 | BC26: 1.57 | BD26: 4.75 | BE26: 5.66 | BF26: 4.87 | BG26: 4.68 | BH26: 4.78 | BI26: 4.54
B27: Healthy | C27: HP-22 | D27: 4.04 | E27: 3.01 | F27: 5.17 | G27: 5.15 | H27: 5.31 | I27: 2.21 | J27: 3.6 | K27: 2.85 | L27: 3.21 | M27: 3.2 | N27: 3.54 | O27: 3.61 | P27: =IFERROR(STDEVA(D27:H27),#N/A) -> 0.99407243 | Q27: =MEDIAN(D27:H27) -> 5.15 | R27: =MAX(J27:O27) -> 3.61 | S27: =100*(R27-Q27)/Q27 -> -29.902913
B28: Healthy | C28: HP-30 | D28: 1.34 | E28: 2.04 | F28: 2.42 | G28: 2.48 | H28: 2.04 | I28: 1.67 | J28: 1.53 | K28: 2.47 | L28: 2.83 | M28: 2.65 | N28: 2.8 | O28: 2.68 | P28: =IFERROR(STDEVA(D28:H28),#N/A) -> 0.45418058 | Q28: =MEDIAN(D28:H28) -> 2.04 | R28: =MAX(J28:O28) -> 2.83 | S28: =100*(R28-Q28)/Q28 -> 38.72549
B29: Healthy | C29: HP-38 | D29: 2.61 | E29: 2.21 | F29: 2.05 | G29: 2.18 | H29: 2.3 | I29: 2.3 | J29: 3.03 | K29: 2.3 | L29: 1.65 | M29: 2.13 | N29: 2.05 | O29: 1.87 | P29: =IFERROR(STDEVA(D29:H29),#N/A) -> 0.21011901 | Q29: =MEDIAN(D29:H29) -> 2.21 | R29: =MAX(J29:O29) -> 3.03 | S29: =100*(R29-Q29)/Q29 -> 37.104072
P30: Mean of median | Q30: =AVERAGE(Q23:Q29) -> 2.5828571 | R30: =AVERAGE(R21:R29) -> 3.5442857 | S30: =AVERAGE(S23:S29) -> 60.979343
P31: SD | Q31: =STDEVA(Q19:Q29) -> 1.3185309 | R31: =STDEVA(R21:R29) -> 0.79653117 | S31: =STDEVA(S23:S29) -> 69.636978
P32: COV | Q32: =Q31/Q30 -> 0.51049317 | R32: =R31/R30 -> 0.22473673 | S32: =S31/S30 -> 1.1419765
O33: Number of scans per subject | P33: 5 | Q33: <-insert correct numbers before the analysis | AE33: Number of scans per subject | AF33: 5 | AG33: <-insert correct numbers before the analysis | AT33: Number of scans per subject | AU33: 5 | AV33: <-insert correct numbers before the analysis | BI33: Number of scans per subject | BJ33: 5 | BK33: <-insert correct numbers before the analysis
O34: Number of subjects | P34: 7 | Q34: <-insert correct numbers before the analysis | AE34: Number of subjects | AF34: 10 | AG34: <-insert correct numbers before the analysis | AT34: Number of subjects | AU34: 10 | AV34: <-insert correct numbers before the analysis | BI34: Number of subjects | BJ34: 10 | BK34: <-insert correct numbers before the analysis
O35: Within SD | P35: =SQRT(AVERAGE(P23:P32)) -> 0.63007325 | AE35: Within SD | AF35: =SQRT(AVERAGE(AF23:AF32)) -> #DIV/0! | AT35: Within SD | AU35: =SQRT(AVERAGE(AU23:AU32)) -> #DIV/0! | BI35: Within SD | BJ35: =SQRT(AVERAGE(BJ23:BJ32)) -> #DIV/0!
O36: CR | P36: =2.77*P35 -> 1.7453029 | AE36: CR | AF36: =2.77*AF35 -> #DIV/0! | AT36: CR | AU36: =2.77*AU35 -> #DIV/0! | BI36: CR | BJ36: =2.77*BJ35 -> #DIV/0!
O37: CI_A | P37: =P36-(1.96*(P35/(SQRT(2*P34*(P33-1))))) -> 1.5802766 | AE37: CI_A | AF37: =AF36-(1.96*(AF35/(SQRT(2*AF34*(AF33-1))))) -> #DIV/0! | AT37: CI_A | AU37: =AU36-(1.96*(AU35/(SQRT(2*AU34*(AU33-1))))) -> #DIV/0! | BI37: CI_A | BJ37: =BJ36-(1.96*(BJ35/(SQRT(2*BJ34*(BJ33-1))))) -> #DIV/0!
O38: CI_B | P38: =P36+(1.96*(P35/(SQRT(2*P34*(P33-1))))) -> 1.9103292 | AE38: CI_B | AF38: =AF36+(1.96*(AF35/(SQRT(2*AF34*(AF33-1))))) -> #DIV/0! | AT38: CI_B | AU38: =AU36+(1.96*(AU35/(SQRT(2*AU34*(AU33-1))))) -> #DIV/0! | BI38: CI_B | BJ38: =BJ36+(1.96*(BJ35/(SQRT(2*BJ34*(BJ33-1))))) -> #DIV/0!
A40: 40-49 | B40: Healthy | C40: HP-12 | D40: 1.89 | E40: 2.28 | F40: 2.15 | G40: 2.26 | H40: 2.12 | I40: 0.99 | J40: 3.03 | K40: 2.58 | L40: 2.55 | M40: 2.5 | P40: =IFERROR(STDEVA(D40:H40),#N/A) -> 0.15572412 | Q40: =MEDIAN(D40:H40) -> 2.15 | R40: =MAX(J40:O40) -> 3.03 | S40: =100*(R40-Q40)/Q40 -> 40.930233
B41: Healthy | C41: HP-15 | D41: 1.23 | E41: 1.14 | F41: 0.88 | G41: 1.06 | H41: 1.16 | I41: 0.59 | J41: 2.76 | K41: 2.49 | L41: 1.91 | M41: 1.54 | P41: =IFERROR(STDEVA(D41:H41),#N/A) -> 0.13408952 | Q41: =MEDIAN(D41:H41) -> 1.14 | R41: =MAX(J41:O41) -> 2.76 | S41: =100*(R41-Q41)/Q41 -> 142.10526
B42: Healthy | C42: HP-20 | D42: 2.01 | E42: 2.05 | F42: 1.93 | G42: 2.34 | H42: 2.32 | I42: 1.87 | J42: 4.24 | K42: 3.32 | L42: 2.9 | M42: 2.71 | N42: 2.21 | O42: 3.46 | P42: =IFERROR(STDEVA(D42:H42),#N/A) -> 0.18774983 | Q42: =MEDIAN(D42:H42) -> 2.05 | R42: =MAX(J42:O42) -> 4.24 | S42: =100*(R42-Q42)/Q42 -> 106.82927 | T42: 2.36 | U42: 2.53 | V42: 2.26 | W42: 2.17 | X42: 2.68 | Y42: 1.3 | Z42: 4.05 | AA42: 4.25 | AB42: 3.74 | AC42: 3.01 | AD42: 2.3 | AE42: 2.91 | AI42: 2.05 | AJ42: 2.51 | AK42: 2.99 | AL42: 2.82 | AM42: 3.58 | AN42: 1.19 | AO42: 4.17 | AP42: 3.73 | AQ42: 3.73 | AR42: 3.2 | AS42: 2.68 | AT42: 2.87 | AX42: 2.26 | AY42: 2.26 | AZ42: 2.89 | BA42: 2.92 | BB42: 2.86 | BC42: 1.18 | BD42: 3.73 | BE42: 4.03 | BF42: 3.74 | BG42: 2.97 | BH42: 3.08 | BI42: 3.66
...

Sheet Mean diameter
D1: SESSION 1 | P1: Coefficient of repeatibility analysis from the baseline scans | T1: SESSION 2 | AF1: Coefficient of repeatibility analysis from the baseline scans | AI1: SESSION 3 | AU1: Coefficient of repeatibility analysis from the baseline scans | AX1: SESSION 4 | BJ1: Coefficient of repeatibility analysis from the baseline scans
D2: Baseline | I2: Ischemia | J2: PORH | Q2: Median value of 5 measures | R2: MAX PORH | S2: Absolute diff between PORH and Median | T2: Baseline | Y2: Ischemia | Z2: PORH | AI2: Baseline | AN2: Ischemia | AO2: PORH | AX2: Baseline | BC2: Ischemia | BD2: PORH
A3: Age group | B3: Health/disease | C3: Participant ID | D3: Scan 1 | E3: Scan 2 | F3: Scan 3 | G3: Scan 4 | H3: Scan 5 | I3: Scan 6 | J3: Scan 7 | K3: Scan 8 | L3: Scan 9 | M3: Scan 10 | N3: Scan 11 | O3: Scan 12 | P3: Variance of (SD) | T3: Scan 1 | U3: Scan 2 | V3: Scan 3 | W3: Scan 4 | X3: Scan 5 | Y3: Scan 6 | Z3: Scan 7 | AA3: Scan 8 | AB3: Scan 9 | AC3: Scan 10 | AD3: Scan 11 | AE3: Scan 12 | AF3: Variance of (SD) | AI3: Scan 1 | AJ3: Scan 2 | AK3: Scan 3 | AL3: Scan 4 | AM3: Scan 5 | AN3: Scan 6 | AO3: Scan 7 | AP3: Scan 8 | AQ3: Scan 9 | AR3: Scan 10 | AS3: Scan 11 | AT3: Scan 12 | AU3: Variance of (SD) | AX3: Scan 1 | AY3: Scan 2 | AZ3: Scan 3 | BA3: Scan 4 | BB3: Scan 5 | BC3: Scan 6 | BD3: Scan 7 | BE3: Scan 8 | BF3: Scan 9 | BG3: Scan 10 | BH3: Scan 11 | BI3: Scan 12 | BJ3: Variance of (SD)
B4: Healthy | C4: HP-03 | D4: 62 | E4: 63 | F4: 65 | G4: 61 | H4: 62 | I4: 60 | J4: 68 | K4: 70 | L4: 70 | M4: 66 | P4: =IFERROR(STDEVA(D4:H4),#N/A) -> 1.5165751 | Q4: =MEDIAN(D4:H4) -> 62 | R4: =MAX(J4:O4) -> 70 | S4: =100*(R4-Q4)/Q4 -> 12.903226 | AF4: =IFERROR(STDEVA(T4:X4),#N/A) -> #N/A | AU4: =IFERROR(STDEVA(AI4:AM4),#N/A) -> #N/A | BJ4: =IFERROR(STDEVA(AX4:BB4),#N/A) -> #N/A
B5: Healthy | C5: HP-05 | D5: 63 | E5: 66 | F5: 70 | G5: 69 | H5: 68 | I5: 50 | J5: 71 | K5: 73 | L5: 69 | M5: 68 | P5: =IFERROR(STDEVA(D5:H5),#N/A) -> 2.7748874 | Q5: =MEDIAN(D5:H5) -> 68 | R5: =MAX(J5:O5) -> 73 | S5: =100*(R5-Q5)/Q5 -> 7.3529412 | AF5: =IFERROR(STDEVA(T5:X5),#N/A) -> #N/A | AU5: =IFERROR(STDEVA(AI5:AM5),#N/A) -> #N/A | BJ5: =IFERROR(STDEVA(AX5:BB5),#N/A) -> #N/A
B6: Healthy | C6: HP-06 | D6: 69 | E6: 70 | F6: 70 | G6: 70 | H6: 72 | I6: 56 | J6: 70 | K6: 73 | L6: 71 | M6: 71 | P6: =IFERROR(STDEVA(D6:H6),#N/A) -> 1.0954451 | Q6: =MEDIAN(D6:H6) -> 70 | R6: =MAX(J6:O6) -> 73 | S6: =100*(R6-Q6)/Q6 -> 4.2857143 | AF6: =IFERROR(STDEVA(T6:X6),#N/A) -> #N/A | AU6: =IFERROR(STDEVA(AI6:AM6),#N/A) -> #N/A | BJ6: =IFERROR(STDEVA(AX6:BB6),#N/A) -> #N/A
B7: Healthy | C7: HP-07 | D7: 65 | E7: 68 | F7: 66 | G7: 68 | H7: 67 | I7: 67 | J7: 73 | K7: 78 | L7: 75 | M7: 75 | P7: =IFERROR(STDEVA(D7:H7),#N/A) -> 1.3038405 | Q7: =MEDIAN(D7:H7) -> 67 | R7: =MAX(J7:O7) -> 78 | S7: =100*(R7-Q7)/Q7 -> 16.41791 | AF7: =IFERROR(STDEVA(T7:X7),#N/A) -> #N/A | AU7: =IFERROR(STDEVA(AI7:AM7),#N/A) -> #N/A | BJ7: =IFERROR(STDEVA(AX7:BB7),#N/A) -> #N/A
B8: Healthy | C8: HP-09 | D8: 59 | E8: 57 | F8: 60 | G8: 60 | H8: 58 | I8: 52 | J8: 72 | K8: 72 | L8: 72 | M8: 71 | P8: =IFERROR(STDEVA(D8:H8),#N/A) -> 1.3038405 | Q8: =MEDIAN(D8:H8) -> 59 | R8: =MAX(J8:O8) -> 72 | S8: =100*(R8-Q8)/Q8 -> 22.033898 | AF8: =IFERROR(STDEVA(T8:X8),#N/A) -> #N/A | AU8: =IFERROR(STDEVA(AI8:AM8),#N/A) -> #N/A | BJ8: =IFERROR(STDEVA(AX8:BB8),#N/A) -> #N/A
B9: Healthy | C9: HP-10 | D9: 63 | E9: 62 | F9: 61 | G9: 62 | H9: 58 | I9: 54 | J9: 70 | K9: 60 | L9: 57 | M9: 55 | P9: =IFERROR(STDEVA(D9:H9),#N/A) -> 1.9235384 | Q9: =MEDIAN(D9:H9) -> 62 | R9: =MAX(J9:O9) -> 70 | S9: =100*(R9-Q9)/Q9 -> 12.903226 | AF9: =IFERROR(STDEVA(T9:X9),#N/A) -> #N/A | AU9: =IFERROR(STDEVA(AI9:AM9),#N/A) -> #N/A | BJ9: =IFERROR(STDEVA(AX9:BB9),#N/A) -> #N/A
B10: Healthy | C10: HP-11 | D10: 55 | E10: 59 | F10: 65 | G10: 63 | H10: 61 | I10: 60 | J10: 69 | K10: 74 | L10: 72 | M10: 65 | P10: =IFERROR(STDEVA(D10:H10),#N/A) -> 3.8470768 | Q10: =MEDIAN(D10:H10) -> 61 | R10: =MAX(J10:O10) -> 74 | S10: =100*(R10-Q10)/Q10 -> 21.311475 | AF10: =IFERROR(STDEVA(T10:X10),#N/A) -> #N/A | AU10: =IFERROR(STDEVA(AI10:AM10),#N/A) -> #N/A | BJ10: =IFERROR(STDEVA(AX10:BB10),#N/A) -> #N/A
B11: Healthy | C11: HP-18 | D11: 64 | E11: 64 | F11: 71 | G11: 71 | H11: 72 | I11: 56 | J11: 70 | K11: 75 | L11: 75 | M11: 75 | P11: =IFERROR(STDEVA(D11:H11),#N/A) -> 4.0373258 | Q11: =MEDIAN(D11:H11) -> 71 | R11: =MAX(J11:O11) -> 75 | S11: =100*(R11-Q11)/Q11 -> 5.6338028 | AF11: =IFERROR(STDEVA(T11:X11),#N/A) -> #N/A | AU11: =IFERROR(STDEVA(AI11:AM11),#N/A) -> #N/A | BJ11: =IFERROR(STDEVA(AX11:BB11),#N/A) -> #N/A
B12: Healthy | C12: HP-24 | D12: 56 | E12: 54 | F12: 52 | G12: 52 | H12: 50 | I12: 45 | J12: 55 | K12: 59 | L12: 57 | M12: 57 | N12: 55 | O12: 51 | P12: =IFERROR(STDEVA(D12:H12),#N/A) -> 2.2803509 | Q12: =MEDIAN(D12:H12) -> 52 | R12: =MAX(J12:O12) -> 59 | S12: =100*(R12-Q12)/Q12 -> 13.461538 | AF12: =IFERROR(STDEVA(T12:X12),#N/A) -> #N/A | AU12: =IFERROR(STDEVA(AI12:AM12),#N/A) -> #N/A | BJ12: =IFERROR(STDEVA(AX12:BB12),#N/A) -> #N/A
P13: Mean of median | Q13: =AVERAGE(Q4:Q12) -> 63.555556 | R13: =AVERAGE(R4:R12) -> 71.555556 | S13: =AVERAGE(S4:S12) -> 12.922637 | AF13: =IFERROR(STDEVA(T13:X13),#N/A) -> #N/A | AU13: =IFERROR(STDEVA(AI13:AM13),#N/A) -> #N/A | BJ13: =IFERROR(STDEVA(AX13:BB13),#N/A) -> #N/A
P14: SD | Q14: =STDEVA(Q4:Q12) -> 6.0644685 | R14: =STDEVA(R4:R12) -> 5.3176854 | S14: =STDEVA(S4:S12) -> 6.3702516 | AF14: =IFERROR(STDEVA(T14:X14),#N/A) -> #N/A | AU14: =IFERROR(STDEVA(AI14:AM14),#N/A) -> #N/A | BJ14: =IFERROR(STDEVA(AX14:BB14),#N/A) -> #N/A
P15: COV | Q15: =Q14/Q13 -> 0.095419958 | R15: =R14/R13 -> 0.074315479 | S15: =S14/S13 -> 0.49295292 | AF15: =IFERROR(STDEVA(T15:X15),#N/A) -> #N/A | AU15: =IFERROR(STDEVA(AI15:AM15),#N/A) -> #N/A | BJ15: =IFERROR(STDEVA(AX15:BB15),#N/A) -> #N/A
O16: Number of scans per subject | P16: 5 | Q16: <-insert correct numbers before the analysis | AE16: Number of scans per subject | AF16: 5 | AG16: <-insert correct numbers before the analysis | AT16: Number of scans per subject | AU16: 5 | AV16: <-insert correct numbers before the analysis | BI16: Number of scans per subject | BJ16: 5 | BK16: <-insert correct numbers before the analysis
O17: Number of subjects | P17: 9 | Q17: <-insert correct numbers before the analysis | AE17: Number of subjects | AF17: 10 | AG17: <-insert correct numbers before the analysis | AT17: Number of subjects | AU17: 10 | AV17: <-insert correct numbers before the analysis | BI17: Number of subjects | BJ17: 10 | BK17: <-insert correct numbers before the analysis
O18: Within SD | P18: =SQRT(AVERAGE(P4:P15)) -> 1.4937976 | AE18: Within SD | AF18: =SQRT(AVERAGE(AF4:AF15)) -> #N/A | AT18: Within SD | AU18: =SQRT(AVERAGE(AU4:AU15)) -> #N/A | BI18: Within SD | BJ18: =SQRT(AVERAGE(BJ4:BJ15)) -> #N/A
O19: CR | P19: =2.77*P18 -> 4.1378193 | AE19: CR | AF19: =2.77*AF18 -> #N/A | AT19: CR | AU19: =2.77*AU18 -> #N/A | BI19: CR | BJ19: =2.77*BJ18 -> #N/A
O20: CI_A | P20: =P19-(1.96*(P18/(SQRT(2*P17*(P16-1))))) -> 3.7927696 | AE20: CI_A | AF20: =AF19-(1.96*(AF18/(SQRT(2*AF17*(AF16-1))))) -> #N/A | AT20: CI_A | AU20: =AU19-(1.96*(AU18/(SQRT(2*AU17*(AU16-1))))) -> #N/A | BI20: CI_A | BJ20: =BJ19-(1.96*(BJ18/(SQRT(2*BJ17*(BJ16-1))))) -> #N/A
O21: CI_B | P21: =P19+(1.96*(P18/(SQRT(2*P17*(P16-1))))) -> 4.4828689 | AE21: CI_B | AF21: =AF19+(1.96*(AF18/(SQRT(2*AF17*(AF16-1))))) -> #N/A | AT21: CI_B | AU21: =AU19+(1.96*(AU18/(SQRT(2*AU17*(AU16-1))))) -> #N/A | BI21: CI_B | BJ21: =BJ19+(1.96*(BJ18/(SQRT(2*BJ17*(BJ16-1))))) -> #N/A
A23: 30-39 | B23: Healthy | C23: HP-04 | D23: 66 | E23: 64 | F23: 68 | G23: 68 | H23: 70 | I23: 57 | J23: 73 | K23: 70 | L23: 65 | M23: 64 | P23: =IFERROR(STDEVA(D23:H23),#N/A) -> 2.2803509 | Q23: =MEDIAN(D23:H23) -> 68 | R23: =MAX(J23:O23) -> 73 | S23: =100*(R23-Q23)/Q23 -> 7.3529412
B24: Healthy | C24: HP-08 | D24: 60 | E24: 64 | F24: 64 | G24: 64 | H24: 62 | I24: 62 | J24: 75 | K24: 73 | L24: 74 | M24: 72 | P24: =IFERROR(STDEVA(D24:H24),#N/A) -> 1.7888544 | Q24: =MEDIAN(D24:H24) -> 64 | R24: =MAX(J24:O24) -> 75 | S24: =100*(R24-Q24)/Q24 -> 17.1875
B25: Healthy | C25: HP-19 | D25: 56 | E25: 64 | F25: 57 | G25: 65 | H25: 68 | I25: 62 | J25: 71 | K25: 70 | L25: 77 | M25: 67 | P25: =IFERROR(STDEVA(D25:H25),#N/A) -> 5.2440442 | Q25: =MEDIAN(D25:H25) -> 64 | R25: =MAX(J25:O25) -> 77 | S25: =100*(R25-Q25)/Q25 -> 20.3125
B26: Healthy | C26: HP-21 | D26: 54 | E26: 57 | F26: 54 | G26: 54 | H26: 55 | I26: 43 | J26: 52 | K26: 56 | L26: 52 | M26: 53 | N26: 53 | O26: 52 | P26: =IFERROR(STDEVA(D26:H26),#N/A) -> 1.3038405 | Q26: =MEDIAN(D26:H26) -> 54 | R26: =MAX(J26:O26) -> 56 | S26: =100*(R26-Q26)/Q26 -> 3.7037037 | T26: 54 | U26: 52 | V26: 50 | W26: 50 | X26: 56 | Y26: 34 | Z26: 61 | AA26: 59 | AB26: 59 | AC26: 57 | AD26: 58 | AE26: 59 | AI26: 47 | AJ26: 51 | AK26: 48 | AL26: 49 | AM26: 50 | AN26: 42 | AO26: 54 | AP26: 56 | AQ26: 55 | AR26: 55 | AS26: 54 | AT26: 53 | AX26: 56 | AY26: 57 | AZ26: 56 | BA26: 56 | BB26: 55 | BC26: 45 | BD26: 58 | BE26: 58 | BF26: 56 | BG26: 54 | BH26: 54 | BI26: 55
B27: Healthy | C27: HP-22 | D27: 56 | E27: 56 | F27: 54 | G27: 53 | H27: 56 | I27: 42 | J27: 57 | K27: 58 | L27: 60 | M27: 58 | N27: 58 | O27: 59 | P27: =IFERROR(STDEVA(D27:H27),#N/A) -> 1.4142136 | Q27: =MEDIAN(D27:H27) -> 56 | R27: =MAX(J27:O27) -> 60 | S27: =100*(R27-Q27)/Q27 -> 7.1428571
B28: Healthy | C28: HP-30 | D28: 40 | E28: 50 | F28: 52 | G28: 50 | H28: 51 | I28: 40 | J28: 40 | K28: 45 | L28: 47 | M28: 45 | N28: 47 | O28: 47 | P28: =IFERROR(STDEVA(D28:H28),#N/A) -> 4.8785244 | Q28: =MEDIAN(D28:H28) -> 50 | R28: =MAX(J28:O28) -> 47 | S28: =100*(R28-Q28)/Q28 -> -6
B29: Healthy | C29: HP-38 | D29: 42 | E29: 46 | F29: 51 | G29: 51 | H29: 52 | I29: 43 | J29: 54 | K29: 53 | L29: 46 | M29: 51 | N29: 50 | O29: 47 | P29: =IFERROR(STDEVA(D29:H29),#N/A) -> 4.2778499 | Q29: =MEDIAN(D29:H29) -> 51 | R29: =MAX(J29:O29) -> 54 | S29: =100*(R29-Q29)/Q29 -> 5.8823529
P30: Mean of median | Q30: =AVERAGE(Q19:Q29) -> 58.142857 | R30: =AVERAGE(R21:R29) -> 63.142857 | S30: =AVERAGE(S19:S29) -> 7.940265
P31: SD | Q31: =STDEVA(Q19:Q29) -> 7.12808 | R31: =STDEVA(R21:R29) -> 11.795883 | S31: =STDEVA(S19:S29) -> 8.7185511
P32: COV | Q32: =Q31/Q30 -> 0.12259597 | R32: =R31/R30 -> 0.18681263 | S32: =S31/S30 -> 1.0980177
O36: Number of scans per subject | P36: 5 | Q36: <-insert correct numbers before the analysis | AE36: Number of scans per subject | AF36: 5 | AG36: <-insert correct numbers before the analysis | AT36: Number of scans per subject | AU36: 5 | AV36: <-insert correct numbers before the analysis | BI36: Number of scans per subject | BJ36: 5 | BK36: <-insert correct numbers before the analysis
O37: Number of subjects | P37: 7 | Q37: <-insert correct numbers before the analysis | AE37: Number of subjects | AF37: 10 | AG37: <-insert correct numbers before the analysis | AT37: Number of subjects | AU37: 10 | AV37: <-insert correct numbers before the analysis | BI37: Number of subjects | BJ37: 10 | BK37: <-insert correct numbers before the analysis
O38: Within SD | P38: =SQRT(AVERAGE(P23:P35)) -> 1.7397733 | AE38: Within SD | AF38: =SQRT(AVERAGE(AF23:AF35)) -> #DIV/0! | AT38: Within SD | AU38: =SQRT(AVERAGE(AU23:AU35)) -> #DIV/0! | BI38: Within SD | BJ38: =SQRT(AVERAGE(BJ23:BJ35)) -> #DIV/0!
O39: CR | P39: =2.77*P38 -> 4.819172 | AE39: CR | AF39: =2.77*AF38 -> #DIV/0! | AT39: CR | AU39: =2.77*AU38 -> #DIV/0! | BI39: CR | BJ39: =2.77*BJ38 -> #DIV/0!
O40: CI_A | P40: =P39-(1.96*(P38/(SQRT(2*P37*(P36-1))))) -> 4.3634975 | AE40: CI_A | AF40: =AF39-(1.96*(AF38/(SQRT(2*AF37*(AF36-1))))) -> #DIV/0! | AT40: CI_A | AU40: =AU39-(1.96*(AU38/(SQRT(2*AU37*(AU36-1))))) -> #DIV/0! | BI40: CI_A | BJ40: =BJ39-(1.96*(BJ38/(SQRT(2*BJ37*(BJ36-1))))) -> #DIV/0!
O41: CI_B | P41: =P39+(1.96*(P38/(SQRT(2*P37*(P36-1))))) -> 5.2748465 | AE41: CI_B | AF41: =AF39+(1.96*(AF38/(SQRT(2*AF37*(AF36-1))))) -> #DIV/0! | AT41: CI_B | AU41: =AU39+(1.96*(AU38/(SQRT(2*AU37*(AU36-1))))) -> #DIV/0! | BI41: CI_B | BJ41: =BJ39+(1.96*(BJ38/(SQRT(2*BJ37*(BJ36-1))))) -> #DIV/0!
A43: 40-49 | B43: Healthy | C43: HP-12 | D43: 65 | E43: 70 | F43: 69 | G43: 68 | H43: 66 | I43: 60 | J43: 72 | K43: 71 | L43: 73 | M43: 71 | P43: =IFERROR(STDEVA(D43:H43),#N/A) -> 2.0736441 | Q43: =MEDIAN(D43:H43) -> 68 | R43: =MAX(J43:O43) -> 73 | S43: =100*(R43-Q43)/Q43 -> 7.3529412
B44: Healthy | C44: HP-15 | D44: 55 | E44: 57 | F44: 54 | G44: 56 | H44: 59 | I44: 61 | J44: 68 | K44: 68 | L44: 64 | M44: 62 | P44: =IFERROR(STDEVA(D44:H44),#N/A) -> 1.9235384 | Q44: =MEDIAN(D44:H44) -> 56 | R44: =MAX(J44:O44) -> 68 | S44: =100*(R44-Q44)/Q44 -> 21.428571
B45: Healthy | C45: HP-20 | D45: 48 | E45: 46 | F45: 47 | G45: 50 | H45: 51 | I45: 42 | J45: 57 | K45: 57 | L45: 56 | M45: 52 | N45: 52 | O45: 55 | P45: =IFERROR(STDEVA(D45:H45),#N/A) -> 2.0736441 | Q45: =MEDIAN(D45:H45) -> 48 | R45: =MAX(J45:O45) -> 57 | S45: =100*(R45-Q45)/Q45 -> 18.75 | T45: 46 | U45: 51 | V45: 50 | W45: 50 | X45: 52 | Y45: 41 | Z45: 59 | AA45: 58 | AB45: 56 | AC45: 53 | AD45: 52 | AE45: 50 | AI45: 51 | AJ45: 55 | AK45: 55 | AL45: 56 | AM45: 58 | AN45: 46 | AO45: 60 | AP45: 60 | AQ45: 59 | AR45: 57 | AS45: 56 | AT45: 55 | AX45: 50 | AY45: 53 | AZ45: 55 | BA45: 54 | BB45: 53 | BC45: 46 | BD45: 60 | BE45: 60 | BF45: 58 | BG45: 56 | BH45: 56 | BI45: 55
...

Sheet Median diameter
D1: SESSION 1 | P1: Coefficient of repeatibility analysis from the baseline scans | T1: SESSION 2 | AF1: Coefficient of repeatibility analysis from the baseline scans | AI1: SESSION 3 | AU1: Coefficient of repeatibility analysis from the baseline scans | AX1: SESSION 4 | BJ1: Coefficient of repeatibility analysis from the baseline scans
D2: Baseline | I2: Ischemia | J2: PORH | Q2: Median value of 5 measures | R2: MAX PORH | S2: Absolute diff between PORH and Median | T2: Baseline | Y2: Ischemia | Z2: PORH | AI2: Baseline | AN2: Ischemia | AO2: PORH | AX2: Baseline | BC2: Ischemia | BD2: PORH
A3: Age group | B3: Health/disease | C3: Participant ID | D3: Scan 1 | E3: Scan 2 | F3: Scan 3 | G3: Scan 4 | H3: Scan 5 | I3: Scan 6 | J3: Scan 7 | K3: Scan 8 | L3: Scan 9 | M3: Scan 10 | N3: Scan 11 | O3: Scan 12 | P3: Variance of (SD) | T3: Scan 1 | U3: Scan 2 | V3: Scan 3 | W3: Scan 4 | X3: Scan 5 | Y3: Scan 6 | Z3: Scan 7 | AA3: Scan 8 | AB3: Scan 9 | AC3: Scan 10 | AD3: Scan 11 | AE3: Scan 12 | AF3: Variance of (SD) | AI3: Scan 1 | AJ3: Scan 2 | AK3: Scan 3 | AL3: Scan 4 | AM3: Scan 5 | AN3: Scan 6 | AO3: Scan 7 | AP3: Scan 8 | AQ3: Scan 9 | AR3: Scan 10 | AS3: Scan 11 | AT3: Scan 12 | AU3: Variance of (SD) | AX3: Scan 1 | AY3: Scan 2 | AZ3: Scan 3 | BA3: Scan 4 | BB3: Scan 5 | BC3: Scan 6 | BD3: Scan 7 | BE3: Scan 8 | BF3: Scan 9 | BG3: Scan 10 | BH3: Scan 11 | BI3: Scan 12 | BJ3: Variance of (SD)
B4: Healthy | C4: HP-03 | D4: 62 | E4: 63 | F4: 65 | G4: 63 | H4: 61 | I4: 61 | J4: 69 | K4: 71 | L4: 73 | M4: 68 | P4: =IFERROR(STDEVA(D4:H4),#N/A) -> 1.4832397 | Q4: =MEDIAN(D4:H4) -> 63 | R4: =MAX(J4:O4) -> 73 | S4: =100*(R4-Q4)/Q4 -> 15.873016 | AF4: =IFERROR(STDEVA(T4:X4),#N/A) -> #N/A | AU4: =IFERROR(STDEVA(AI4:AM4),#N/A) -> #N/A | BJ4: =IFERROR(STDEVA(AX4:BB4),#N/A) -> #N/A
B5: Healthy | C5: HP-05 | D5: 63 | E5: 66 | F5: 72 | G5: 70 | H5: 71 | I5: 49 | J5: 73 | K5: 74 | L5: 70 | M5: 70 | P5: =IFERROR(STDEVA(D5:H5),#N/A) -> 3.7815341 | Q5: =MEDIAN(D5:H5) -> 70 | R5: =MAX(J5:O5) -> 74 | S5: =100*(R5-Q5)/Q5 -> 5.7142857 | AF5: =IFERROR(STDEVA(T5:X5),#N/A) -> #N/A | AU5: =IFERROR(STDEVA(AI5:AM5),#N/A) -> #N/A | BJ5: =IFERROR(STDEVA(AX5:BB5),#N/A) -> #N/A
B6: Healthy | C6: HP-06 | D6: 70 | E6: 71 | F6: 73 | G6: 72 | H6: 73 | I6: 56 | J6: 72 | K6: 77 | L6: 74 | M6: 74 | P6: =IFERROR(STDEVA(D6:H6),#N/A) -> 1.3038405 | Q6: =MEDIAN(D6:H6) -> 72 | R6: =MAX(J6:O6) -> 77 | S6: =100*(R6-Q6)/Q6 -> 6.9444444 | AF6: =IFERROR(STDEVA(T6:X6),#N/A) -> #N/A | AU6: =IFERROR(STDEVA(AI6:AM6),#N/A) -> #N/A | BJ6: =IFERROR(STDEVA(AX6:BB6),#N/A) -> #N/A
B7: Healthy | C7: HP-07 | D7: 68 | E7: 68 | F7: 69 | G7: 69 | H7: 69 | I7: 70 | J7: 75 | K7: 81 | L7: 76 | M7: 77 | P7: =IFERROR(STDEVA(D7:H7),#N/A) -> 0.54772256 | Q7: =MEDIAN(D7:H7) -> 69 | R7: =MAX(J7:O7) -> 81 | S7: =100*(R7-Q7)/Q7 -> 17.391304 | AF7: =IFERROR(STDEVA(T7:X7),#N/A) -> #N/A | AU7: =IFERROR(STDEVA(AI7:AM7),#N/A) -> #N/A | BJ7: =IFERROR(STDEVA(AX7:BB7),#N/A) -> #N/A
B8: Healthy | C8: HP-09 | D8: 59 | E8: 56 | F8: 60 | G8: 60 | H8: 59 | I8: 50 | J8: 74 | K8: 75 | L8: 74 | M8: 73 | P8: =IFERROR(STDEVA(D8:H8),#N/A) -> 1.6431677 | Q8: =MEDIAN(D8:H8) -> 59 | R8: =MAX(J8:O8) -> 75 | S8: =100*(R8-Q8)/Q8 -> 27.118644 | AF8: =IFERROR(STDEVA(T8:X8),#N/A) -> #N/A | AU8: =IFERROR(STDEVA(AI8:AM8),#N/A) -> #N/A | BJ8: =IFERROR(STDEVA(AX8:BB8),#N/A) -> #N/A
B9: Healthy | C9: HP-10 | D9: 63 | E9: 62 | F9: 61 | G9: 61 | H9: 58 | I9: 54 | J9: 72 | K9: 61 | L9: 58 | M9: 57 | P9: =IFERROR(STDEVA(D9:H9),#N/A) -> 1.8708287 | Q9: =MEDIAN(D9:H9) -> 61 | R9: =MAX(J9:O9) -> 72 | S9: =100*(R9-Q9)/Q9 -> 18.032787 | AF9: =IFERROR(STDEVA(T9:X9),#N/A) -> #N/A | AU9: =IFERROR(STDEVA(AI9:AM9),#N/A) -> #N/A | BJ9: =IFERROR(STDEVA(AX9:BB9),#N/A) -> #N/A
B10: Healthy | C10: HP-11 | D10: 55 | E10: 60 | F10: 66 | G10: 63 | H10: 62 | I10: 60 | J10: 71 | K10: 77 | L10: 73 | M10: 67 | P10: =IFERROR(STDEVA(D10:H10),#N/A) -> 4.0865633 | Q10: =MEDIAN(D10:H10) -> 62 | R10: =MAX(J10:O10) -> 77 | S10: =100*(R10-Q10)/Q10 -> 24.193548 | AF10: =IFERROR(STDEVA(T10:X10),#N/A) -> #N/A | AU10: =IFERROR(STDEVA(AI10:AM10),#N/A) -> #N/A | BJ10: =IFERROR(STDEVA(AX10:BB10),#N/A) -> #N/A
B11: Healthy | C11: HP-18 | D11: 66 | E11: 66 | F11: 74 | G11: 74 | H11: 74 | I11: 54 | J11: 73 | K11: 78 | L11: 78 | M11: 77 | P11: =IFERROR(STDEVA(D11:H11),#N/A) -> 4.3817805 | Q11: =MEDIAN(D11:H11) -> 74 | R11: =MAX(J11:O11) -> 78 | S11: =100*(R11-Q11)/Q11 -> 5.4054054 | AF11: =IFERROR(STDEVA(T11:X11),#N/A) -> #N/A | AU11: =IFERROR(STDEVA(AI11:AM11),#N/A) -> #N/A | BJ11: =IFERROR(STDEVA(AX11:BB11),#N/A) -> #N/A
